Traceback (most recent call last):
  File "C:\Programs\hybrid_auth_project\venv\lib\site-packages\sqlalchemy\engine\base.py", line 1964, in _exec_single_context
    self.dialect.do_execute(
  File "C:\Programs\hybrid_auth_project\venv\lib\site-packages\sqlalchemy\engine\default.py", line 945, in do_execute
    cursor.execute(statement, parameters)
sqlite3.OperationalError: no such table: users

The above exception was the direct cause of the following exception:

Traceback (most recent call last):
  File "C:\Programs\hybrid_auth_project\setup_db.py", line 15, in <module>
    db.session.commit()
  File "C:\Programs\hybrid_auth_project\venv\lib\site-packages\sqlalchemy\orm\scoping.py", line 599, in commit
    return self._proxied.commit()
  File "C:\Programs\hybrid_auth_project\venv\lib\site-packages\sqlalchemy\orm\session.py", line 2032, in commit
    trans.commit(_to_root=True)
  File "<string>", line 2, in commit
  File "C:\Programs\hybrid_auth_project\venv\lib\site-packages\sqlalchemy\orm\state_changes.py", line 139, in _go
    ret_value = fn(self, *arg, **kw)
  File "C:\Programs\hybrid_auth_project\venv\lib\site-packages\sqlalchemy\orm\session.py", line 1313, in commit
    self._prepare_impl()
  File "<string>", line 2, in _prepare_impl
  File "C:\Programs\hybrid_auth_project\venv\lib\site-packages\sqlalchemy\orm\state_changes.py", line 139, in _go
    ret_value = fn(self, *arg, **kw)
  File "C:\Programs\hybrid_auth_project\venv\lib\site-packages\sqlalchemy\orm\session.py", line 1288, in _prepare_impl
    self.session.flush()
  File "C:\Programs\hybrid_auth_project\venv\lib\site-packages\sqlalchemy\orm\session.py", line 4353, in flush
    self._flush(objects)
  File "C:\Programs\hybrid_auth_project\venv\lib\site-packages\sqlalchemy\orm\session.py", line 4488, in _flush
    with util.safe_reraise():
  File "C:\Programs\hybrid_auth_project\venv\lib\site-packages\sqlalchemy\util\langhelpers.py", line 146, in __exit__
    raise exc_value.with_traceback(exc_tb)
  File "C:\Programs\hybrid_auth_project\venv\lib\site-packages\sqlalchemy\orm\session.py", line 4449, in _flush
    flush_context.execute()
  File "C:\Programs\hybrid_auth_project\venv\lib\site-packages\sqlalchemy\orm\unitofwork.py", line 466, in execute
    rec.execute(self)
  File "C:\Programs\hybrid_auth_project\venv\lib\site-packages\sqlalchemy\orm\unitofwork.py", line 642, in execute
    util.preloaded.orm_persistence.save_obj(
  File "C:\Programs\hybrid_auth_project\venv\lib\site-packages\sqlalchemy\orm\persistence.py", line 93, in save_obj
    _emit_insert_statements(
  File "C:\Programs\hybrid_auth_project\venv\lib\site-packages\sqlalchemy\orm\persistence.py", line 1233, in _emit_insert_statements
    result = connection.execute(
  File "C:\Programs\hybrid_auth_project\venv\lib\site-packages\sqlalchemy\engine\base.py", line 1416, in execute
    return meth(
  File "C:\Programs\hybrid_auth_project\venv\lib\site-packages\sqlalchemy\sql\elements.py", line 523, in _execute_on_connection
    return connection._execute_clauseelement(
  File "C:\Programs\hybrid_auth_project\venv\lib\site-packages\sqlalchemy\engine\base.py", line 1638, in _execute_clauseelement
    ret = self._execute_context(
  File "C:\Programs\hybrid_auth_project\venv\lib\site-packages\sqlalchemy\engine\base.py", line 1843, in _execute_context
    return self._exec_single_context(
  File "C:\Programs\hybrid_auth_project\venv\lib\site-packages\sqlalchemy\engine\base.py", line 1983, in _exec_single_context
    self._handle_dbapi_exception(
  File "C:\Programs\hybrid_auth_project\venv\lib\site-packages\sqlalchemy\engine\base.py", line 2352, in _handle_dbapi_exception
    raise sqlalchemy_exception.with_traceback(exc_info[2]) from e
  File "C:\Programs\hybrid_auth_project\venv\lib\site-packages\sqlalchemy\engine\base.py", line 1964, in _exec_single_context
    self.dialect.do_execute(
  File "C:\Programs\hybrid_auth_project\venv\lib\site-packages\sqlalchemy\engine\default.py", line 945, in do_execute
    cursor.execute(statement, parameters)
sqlalchemy.exc.OperationalError: (sqlite3.OperationalError) no such table: users
[SQL: INSERT INTO users (username, password_hash) VALUES (?, ?)]
[parameters: ('testuser', 'scrypt:32768:8:1$wl9n1bRDnYIru73V$32136371b2869ce44e8f1849cd005ab56f98a40f766848ff886e9e45548bf5f81d6cec6b1e8a5bbd65363378bbb1b4674d12d44f0daba82bba26d9b7d1579aed')]
(Background on this error at: https://sqlalche.me/e/20/e3q8)